#VRML_SIM R2023b utf8
# license: MIT
# license url: https://github.com/DeepBlueRobotics/DeepBlueSim/blob/master/LICENSE.md
# template language: javascript
# A SliderJoint powered by a DeepBlueSim-compatible motor

EXTERNPROTO "DBSLinearMotorBase.proto"
EXTERNPROTO "PreconfiguredDBSLinearMotor.proto"

EXTERNPROTO "CANCoder.proto"
EXTERNPROTO "DBSQuadratureEncoder.proto"
EXTERNPROTO "REVBuiltinEncoder.proto"
EXTERNPROTO "SparkMaxAbsoluteEncoder.proto"
EXTERNPROTO "SparkMaxAlternateEncoder.proto"
EXTERNPROTO "SparkMaxAnalogSensor.proto"

PROTO PoweredSliderJoint [
    field MFNode{
        DBSLinearMotorBase{}, PreconfiguredDBSLinearMotor{}
        CANCoder{}, DBSQuadratureEncoder{}, REVBuiltinEncoder{}, SparkMaxAbsoluteEncoder{}, SparkMaxAlternateEncoder{}, SparkMaxAnalogSensor{},
        Brake{}
    } devices [PreconfiguredDBSLinearMotor{} REVBuiltinEncoder{} Brake{}]
    field SFNode{Solid{}} endPoint Solid{}
    field SFNode{JointParameters{}} jointParameters JointParameters{}
]
{
    %<
        import {assert} from 'wbutility.js';
        let devices = fields.devices.value;
        let hasBrake = false;
        let motorDevice = null;
        let encoderDevice = null;
        for (let i = 0; i < devices.length; i++) {
            let node_name = devices[i].node_name;
            if (node_name === "Brake") {
                hasBrake = true;
            } else if (node_name.endsWith("Motor")) {
                motorDevice = devices[i];
            } else if (node_name.endsWith("Encoder")) {
                encoderDevice = devices[i];
            }
        }
        assert(hasBrake, "PoweredSliderJoint is missing the required Brake device!");
        assert(motorDevice !== null, "PoweredSliderJoint is missing the required motor device!");
        let motorType = motorDevice?.node_name;
        let controllerType = motorDevice?.fields.controllerType.value;
        if (controllerType?.startsWith("Spark")) {
            assert(encoderDevice !== null, "PoweredSliderJoint is using a " + controllerType + " motor controller but is missing the required encoder device! "
                + "Consider adding a REVBuiltinEncoder.");
        } else if (controllerType === "PWM") {
            let encoderType = encoderDevice?.node_name;
            assert(!encoderType?.endsWith("BuiltinEncoder"), "PoweredSliderJoint is using a " + controllerType + " motor controller, so a built-in encoder is not allowed!");
        }
    >%
    SliderJoint {
        device IS devices
        endPoint IS endPoint
        jointParameters IS jointParameters
    }
}
