#VRML_SIM R2023b utf8
# license: MIT
# license url: https://github.com/DeepBlueRobotics/DeepBlueSim/blob/master/LICENSE.md
# template language: javascript
# A HingeJoint powered by a DeepBlueSim-compatible motor

EXTERNPROTO "DBSRotationalMotorBase.proto"
EXTERNPROTO "PreconfiguredDBSRotationalMotor.proto"

EXTERNPROTO "CANCoder.proto"
EXTERNPROTO "DBSQuadratureEncoder.proto"
EXTERNPROTO "REVBuiltinEncoder.proto"
EXTERNPROTO "SparkMaxAbsoluteEncoder.proto"
EXTERNPROTO "SparkMaxAlternateEncoder.proto"
EXTERNPROTO "SparkMaxAnalogSensor.proto"

EXTERNPROTO "DBSBrake.proto"

PROTO PoweredHinge2Joint [
    field MFNode{
        DBSRotationalMotorBase{}, PreconfiguredDBSRotationalMotor{}
        CANCoder{}, DBSQuadratureEncoder{}, REVBuiltinEncoder{}, SparkMaxAbsoluteEncoder{}, SparkMaxAlternateEncoder{}, SparkMaxAnalogSensor{},
        DBSBrake{}
    } devices [PreconfiguredDBSRotationalMotor{} REVBuiltinEncoder{} DBSBrake{}]
    field MFNode{
        DBSRotationalMotorBase{}, PreconfiguredDBSRotationalMotor{}
        CANCoder{}, DBSQuadratureEncoder{}, REVBuiltinEncoder{}, SparkMaxAbsoluteEncoder{}, SparkMaxAlternateEncoder{}, SparkMaxAnalogSensor{},
        DBSBrake{}
    } devices2 [PreconfiguredDBSRotationalMotor{} REVBuiltinEncoder{} DBSBrake{}]
    field SFNode{Solid{}} endPoint Solid{}
    field SFNode{HingeJointParameters{}} jointParameters HingeJointParameters{}
    field SFNode{JointParameters{}} jointParameters2 JointParameters{}
]
{
    %<
        import {assert} from 'wbutility.js';
        let dbsutility = eval(wbfile.readTextFile(`${context.project_path}protos/deepbluesim/dbsutility.js`));
        dbsutility.assertValidPoweredJointDevices(fields.devices.value, "PoweredHinge2Joint.devices", assert);
        dbsutility.assertValidPoweredJointDevices(fields.devices2.value, "PoweredHinge2Joint.devices2", assert);
    >%
    Hinge2Joint {
        device IS devices
        device2 IS devices2
        endPoint IS endPoint
        jointParameters IS jointParameters
        jointParameters2 IS jointParameters2
    }
}
